<?xml version="1.0" encoding="utf-8"?>
<!-- This URDF was automatically created by SolidWorks to URDF Exporter! Originally created by Stephen Brawner (brawner@gmail.com) 
     Commit Version: 1.6.0-4-g7f85cfe  Build Version: 1.6.7995.38578
     For more information, please see http://wiki.ros.org/sw_urdf_exporter -->
<robot
  name="spider_description">
  <link
    name="base_link">
    <inertial>
      <origin
        xyz="0.000117294646229485 -0.000103910769588017 0.344546759775775"
        rpy="0 0 0" />
      <mass
        value="0.90676996728754" />
      <inertia
        ixx="0.00222083775289733"
        ixy="2.94491905712168E-08"
        ixz="-7.88731937170433E-15"
        iyy="0.00782569778934277"
        iyz="-3.64878371586986E-10"
        izz="0.00996701141519793" />
    </inertial>
    <visual>
      <origin
        xyz="0 0 0"
        rpy="0 0 0" />
      <geometry>
        <mesh
          filename="file://$(find spider_description)/meshes/base_link.STL" />
      </geometry>
      <material
        name="">
        <color
          rgba="0.250980392156863 0.250980392156863 0.250980392156863 1" />
      </material>
    </visual>
    <collision>
      <origin
        xyz="0 0 0"
        rpy="0 0 0" />
      <geometry>
        <mesh
          filename="file://$(find spider_description)/meshes/base_link.STL" />
      </geometry>
    </collision>
  </link>
  <link
    name="l1u_link">
    <inertial>
      <origin
        xyz="0.154419948673766 -0.108071257181778 -0.0262073664538632"
        rpy="0 0 0" />
      <mass
        value="0.121556929446906" />
      <inertia
        ixx="2.98692436170354E-05"
        ixy="6.01737504568314E-06"
        ixz="1.39996684702746E-07"
        iyy="8.34753717526043E-05"
        iyz="-1.83841775517374E-08"
        izz="8.98886608131818E-05" />
    </inertial>
    <visual>
      <origin
        xyz="0 0 0"
        rpy="0 0 0" />
      <geometry>
        <mesh
          filename="file://$(find spider_description)/meshes/l1u_link.STL" />
      </geometry>
      <material
        name="">
        <color
          rgba="0.898039215686275 0.917647058823529 0.929411764705882 1" />
      </material>
    </visual>
    <collision>
      <origin
        xyz="0 0 0"
        rpy="0 0 0" />
      <geometry>
        <mesh
          filename="file://$(find spider_description)/meshes/l1u_link.STL" />
      </geometry>
    </collision>
  </link>
  <joint
    name="l1u_joint"
    type="revolute">
    <origin
      xyz="0.135325236036619 0.065795940603256 0.32480996558412"
      rpy="0 0 -0.745770822015801" />
    <parent
      link="base_link" />
    <child
      link="l1u_link" />
    <axis
      xyz="0 0 1" />
    <limit
      lower="-2"
      upper="2"
      effort="10.3"
      velocity="5.5" />
  </joint>
  <link
    name="l1m_link">
    <inertial>
      <origin
        xyz="0.286981762593124 -0.167836221232245 0.139790330185309"
        rpy="0 0 0" />
      <mass
        value="0.161135069271916" />
      <inertia
        ixx="0.000399051527822622"
        ixy="1.22629309696053E-05"
        ixz="-0.000182191791171063"
        iyy="0.000495379003994907"
        iyz="2.2854419119569E-05"
        izz="0.000134963700775246" />
    </inertial>
    <visual>
      <origin
        xyz="0 0 0"
        rpy="0 0 0" />
      <geometry>
        <mesh
          filename="file://$(find spider_description)/meshes/l1m_link.STL" />
      </geometry>
      <material
        name="">
        <color
          rgba="0.968627450980392 0.258823529411765 0.258823529411765 1" />
      </material>
    </visual>
    <collision>
      <origin
        xyz="0 0 0"
        rpy="0 0 0" />
      <geometry>
        <mesh
          filename="file://$(find spider_description)/meshes/l1m_link.STL" />
      </geometry>
    </collision>
  </link>
  <joint
    name="l1m_joint"
    type="revolute">
    <origin
      xyz="-0.030557 0.087023 -0.0267"
      rpy="0 0 0" />
    <parent
      link="l1u_link" />
    <child
      link="l1m_link" />
    <axis
      xyz="-1 0 0" />
    <limit
      lower="-2"
      upper="2"
      effort="10.3"
      velocity="5.5" />
  </joint>
  <link
    name="l1l_link">
    <inertial>
      <origin
        xyz="-0.43617 0.25584 0.044125"
        rpy="0 0 0" />
      <mass
        value="0.23232" />
      <inertia
        ixx="0.0032789"
        ixy="0.0017565"
        ixz="-0.00088572"
        iyy="0.0020048"
        iyz="0.0013307"
        izz="0.0039063" />
    </inertial>
    <visual>
      <origin
        xyz="0 0 0"
        rpy="0 0 0" />
      <geometry>
        <mesh
          filename="file://$(find spider_description)/meshes/l1l_link.STL" />
      </geometry>
      <material
        name="">
        <color
          rgba="1 1 1 1" />
      </material>
    </visual>
    <collision>
      <origin
        xyz="0 0 0"
        rpy="0 0 0" />
      <geometry>
        <mesh
          filename="file://$(find spider_description)/meshes/l1l_link.STL" />
      </geometry>
    </collision>
  </link>
  <joint
    name="l1l_joint"
    type="revolute">
    <origin
      xyz="0.0213912128437282 -0.0534436133185651 0.210645997371251"
      rpy="-1.02142189220107 0 -3.14159265358979" />
    <parent
      link="l1m_link" />
    <child
      link="l1l_link" />
    <axis
      xyz="-1 0 0" />
    <limit
      lower="-2"
      upper="2"
      effort="10.3"
      velocity="5.5" />
  </joint>
  <link
    name="l2u_link">
    <inertial>
      <origin
        xyz="0.0469207293648169 -0.228535333755799 -0.0262073660314697"
        rpy="0 0 0" />
      <mass
        value="0.121556934479711" />
      <inertia
        ixx="7.87107079534156E-05"
        ixy="1.63988430425469E-05"
        ixz="4.1687667022373E-08"
        iyy="3.46339067832967E-05"
        iyz="-1.34904118126691E-07"
        izz="8.98886614753046E-05" />
    </inertial>
    <visual>
      <origin
        xyz="0 0 0"
        rpy="0 0 0" />
      <geometry>
        <mesh
          filename="file://$(find spider_description)/meshes/l2u_link.STL" />
      </geometry>
      <material
        name="">
        <color
          rgba="0.898039215686275 0.917647058823529 0.929411764705882 1" />
      </material>
    </visual>
    <collision>
      <origin
        xyz="0 0 0"
        rpy="0 0 0" />
      <geometry>
        <mesh
          filename="file://$(find spider_description)/meshes/l2u_link.STL" />
      </geometry>
    </collision>
  </link>
  <joint
    name="l2u_joint"
    type="revolute">
    <origin
      xyz="0.0559114070065679 0.0854187677387983 0.32480996558412"
      rpy="0 0 -0.176563302439027" />
    <parent
      link="base_link" />
    <child
      link="l2u_link" />
    <axis
      xyz="0 0 1" />
    <limit
      lower="-2"
      upper="2"
      effort="10.3"
      velocity="5.5" />
  </joint>
  <link
    name="l2m_link">
    <inertial>
      <origin
        xyz="0.0935459919176962 -0.409866991779806 0.133252954924736"
        rpy="0 0 0" />
      <mass
        value="0.161135070605957" />
      <inertia
        ixx="0.000484924627535035"
        ixy="3.79570698056236E-05"
        ixz="-6.11578757513043E-05"
        iyy="0.000376763937000654"
        iyz="0.000193649924861982"
        izz="0.000167705667111695" />
    </inertial>
    <visual>
      <origin
        xyz="0 0 0"
        rpy="0 0 0" />
      <geometry>
        <mesh
          filename="file://$(find spider_description)/meshes/l2m_link.STL" />
      </geometry>
      <material
        name="">
        <color
          rgba="0.792156862745098 0.819607843137255 0.933333333333333 1" />
      </material>
    </visual>
    <collision>
      <origin
        xyz="0 0 0"
        rpy="0 0 0" />
      <geometry>
        <mesh
          filename="file://$(find spider_description)/meshes/l2m_link.STL" />
      </geometry>
    </collision>
  </link>
  <joint
    name="l2m_joint"
    type="revolute">
    <origin
      xyz="0.0241999999999997 0.0890000000000009 -0.0267000000000002"
      rpy="0 0 0" />
    <parent
      link="l2u_link" />
    <child
      link="l2m_link" />
    <axis
      xyz="-1 0 0" />
    <limit
      lower="-2"
      upper="2"
      effort="10.3"
      velocity="5.5" />
  </joint>
  <link
    name="l2l_link">
    <inertial>
      <origin
        xyz="-0.122804700994714 0.45645559595592 0.527518423799124"
        rpy="0 0 0" />
      <mass
        value="0.232321735211916" />
      <inertia
        ixx="0.00449736942077841"
        ixy="0.000621160328473533"
        ixz="5.41547870877899E-05"
        iyy="0.000199143862517399"
        iyz="-0.000194993447103531"
        izz="0.0044934751328662" />
    </inertial>
    <visual>
      <origin
        xyz="0 0 0"
        rpy="0 0 0" />
      <geometry>
        <mesh
          filename="file://$(find spider_description)/meshes/l2l_link.STL" />
      </geometry>
      <material
        name="">
        <color
          rgba="1 1 1 1" />
      </material>
    </visual>
    <collision>
      <origin
        xyz="0 0 0"
        rpy="0 0 0" />
      <geometry>
        <mesh
          filename="file://$(find spider_description)/meshes/l2l_link.STL" />
      </geometry>
    </collision>
  </link>
  <joint
    name="l2l_joint"
    type="revolute">
    <origin
      xyz="-0.0126999999999991 0.0877298907248208 0.199568825905779"
      rpy="-1.15433342150992 0 -3.14159265358979" />
    <parent
      link="l2m_link" />
    <child
      link="l2l_link" />
    <axis
      xyz="-1 0 0" />
    <limit
      lower="-2"
      upper="2"
      effort="10.3"
      velocity="5.5" />
  </joint>
  <link
    name="l3u_link">
    <inertial>
      <origin
        xyz="-0.0510381861552839 -0.226959718803476 -0.0262073658893809"
        rpy="0 0 0" />
      <mass
        value="0.121556931312411" />
      <inertia
        ixx="7.83886213852493E-05"
        ixy="-1.68230453634299E-05"
        ixz="-4.8377138934072E-08"
        iyy="3.4955993581283E-05"
        iyz="-1.32652037454451E-07"
        izz="8.98886612776239E-05" />
    </inertial>
    <visual>
      <origin
        xyz="0 0 0"
        rpy="0 0 0" />
      <geometry>
        <mesh
          filename="file://$(find spider_description)/meshes/l3u_link.STL" />
      </geometry>
      <material
        name="">
        <color
          rgba="0.898039215686275 0.917647058823529 0.929411764705882 1" />
      </material>
    </visual>
    <collision>
      <origin
        xyz="0 0 0"
        rpy="0 0 0" />
      <geometry>
        <mesh
          filename="file://$(find spider_description)/meshes/l3u_link.STL" />
      </geometry>
    </collision>
  </link>
  <joint
    name="l3u_joint"
    type="revolute">
    <origin
      xyz="-0.0549203590356081 0.0855522739905491 0.32480996558412"
      rpy="0 0 0.158782370296306" />
    <parent
      link="base_link" />
    <child
      link="l3u_link" />
    <axis
      xyz="0 0 1" />
    <limit
      lower="-2"
      upper="2"
      effort="10.3"
      velocity="5.5" />
  </joint>
  <link
    name="l3m_link">
    <inertial>
      <origin
        xyz="-0.0747995321032311 -0.432705717583594 0.133000542844302"
        rpy="0 0 0" />
      <mass
        value="0.161135066819612" />
      <inertia
        ixx="0.000481795172807279"
        ixy="-4.2285478274507E-05"
        ixz="6.8592348651621E-05"
        iyy="0.000378661150728313"
        iyz="0.000191773263281905"
        izz="0.000168937904731794" />
    </inertial>
    <visual>
      <origin
        xyz="0 0 0"
        rpy="0 0 0" />
      <geometry>
        <mesh
          filename="file://$(find spider_description)/meshes/l3m_link.STL" />
      </geometry>
      <material
        name="">
        <color
          rgba="0.792156862745098 0.819607843137255 0.933333333333333 1" />
      </material>
    </visual>
    <collision>
      <origin
        xyz="0 0 0"
        rpy="0 0 0" />
      <geometry>
        <mesh
          filename="file://$(find spider_description)/meshes/l3m_link.STL" />
      </geometry>
    </collision>
  </link>
  <joint
    name="l3m_joint"
    type="revolute">
    <origin
      xyz="0.0241999999999998 0.0890000000000009 -0.0267000000000002"
      rpy="0 0 0" />
    <parent
      link="l3u_link" />
    <child
      link="l3m_link" />
    <axis
      xyz="-1 0 0" />
    <limit
      lower="-2"
      upper="2"
      effort="10.3"
      velocity="5.5" />
  </joint>
  <link
    name="l3l_link">
    <inertial>
      <origin
        xyz="-0.162601499972518 -0.573477507436548 -0.00802955992153223"
        rpy="0 0 0" />
      <mass
        value="0.232321735211916" />
      <inertia
        ixx="0.00448560324571222"
        ixy="-0.000301852027385005"
        ixz="-0.000584042303331634"
        iyy="0.00374430193244676"
        iyz="-0.00164077208236163"
        izz="0.000960083238003012" />
    </inertial>
    <visual>
      <origin
        xyz="0 0 0"
        rpy="0 0 0" />
      <geometry>
        <mesh
          filename="file://$(find spider_description)/meshes/l3l_link.STL" />
      </geometry>
      <material
        name="">
        <color
          rgba="1 1 1 1" />
      </material>
    </visual>
    <collision>
      <origin
        xyz="0 0 0"
        rpy="0 0 0" />
      <geometry>
        <mesh
          filename="file://$(find spider_description)/meshes/l3l_link.STL" />
      </geometry>
    </collision>
  </link>
  <joint
    name="l3l_joint"
    type="revolute">
    <origin
      xyz="0 0 0"
      rpy="0 0 0" />
    <parent
      link="l3m_link" />
    <child
      link="l3l_link" />
    <axis
      xyz="-1 0 0" />
    <limit
      lower="-2"
      upper="2"
      effort="10.3"
      velocity="5.5" />
  </joint>
  <link
    name="l4u_link">
    <inertial>
      <origin
        xyz="-0.146337430573637 -0.11111254359386 -0.0263258037069349"
        rpy="0 0 0" />
      <mass
        value="0.121556926367408" />
      <inertia
        ixx="3.14124028787741E-05"
        ixy="-1.07958454400881E-05"
        ixz="-1.38871698773613E-07"
        iyy="8.19322117261913E-05"
        iyz="-2.55281384155195E-08"
        izz="8.98886601774634E-05" />
    </inertial>
    <visual>
      <origin
        xyz="0 0 0"
        rpy="0 0 0" />
      <geometry>
        <mesh
          filename="file://$(find spider_description)/meshes/l4u_link.STL" />
      </geometry>
      <material
        name="">
        <color
          rgba="0.898039215686275 0.917647058823529 0.929411764705882 1" />
      </material>
    </visual>
    <collision>
      <origin
        xyz="0 0 0"
        rpy="0 0 0" />
      <geometry>
        <mesh
          filename="file://$(find spider_description)/meshes/l4u_link.STL" />
      </geometry>
    </collision>
  </link>
  <joint
    name="l4u_joint"
    type="revolute">
    <origin
      xyz="-0.134390338047676 0.0661508571431217 0.32480996558412"
      rpy="0 0 0.687067409573743" />
    <parent
      link="base_link" />
    <child
      link="l4u_link" />
    <axis
      xyz="0 0 1" />
    <limit
      lower="-2"
      upper="2"
      effort="10.3"
      velocity="5.5" />
  </joint>
  <link
    name="l4m_link">
    <inertial>
      <origin
        xyz="-0.291357943256108 -0.263596486856658 0.117297885395556"
        rpy="0 0 0" />
      <mass
        value="0.161135071133872" />
      <inertia
        ixx="0.000299234777849973"
        ixy="-3.77220061680142E-05"
        ixz="0.000220268095905799"
        iyy="0.00048971742146975"
        iyz="4.20228584572971E-05"
        izz="0.000240442034795386" />
    </inertial>
    <visual>
      <origin
        xyz="0 0 0"
        rpy="0 0 0" />
      <geometry>
        <mesh
          filename="file://$(find spider_description)/meshes/l4m_link.STL" />
      </geometry>
      <material
        name="">
        <color
          rgba="0.968627450980392 0.258823529411765 0.258823529411765 1" />
      </material>
    </visual>
    <collision>
      <origin
        xyz="0 0 0"
        rpy="0 0 0" />
      <geometry>
        <mesh
          filename="file://$(find spider_description)/meshes/l4m_link.STL" />
      </geometry>
    </collision>
  </link>
  <joint
    name="l4m_joint"
    type="revolute">
    <origin
      xyz="0.0241999999926198 0.0889999999975515 -0.0266999999938015"
      rpy="0 0 0" />
    <parent
      link="l4u_link" />
    <child
      link="l4m_link" />
    <axis
      xyz="-1 0 0" />
    <limit
      lower="-2"
      upper="2"
      effort="10.3"
      velocity="5.5" />
  </joint>
  <link
    name="l4l_link">
    <inertial>
      <origin
        xyz="0.451969689696873 0.356887844969793 0.21727223031826"
        rpy="0 0 0" />
      <mass
        value="0.232321735211916" />
      <inertia
        ixx="0.00367926259351953"
        ixy="-0.00161459441465913"
        ixz="0.000571986396848949"
        iyy="0.00136146395722692"
        iyz="0.00119075626010597"
        izz="0.00414926186541554" />
    </inertial>
    <visual>
      <origin
        xyz="0 0 0"
        rpy="0 0 0" />
      <geometry>
        <mesh
          filename="file://$(find spider_description)/meshes/l4l_link.STL" />
      </geometry>
      <material
        name="">
        <color
          rgba="1 1 1 1" />
      </material>
    </visual>
    <collision>
      <origin
        xyz="0 0 0"
        rpy="0 0 0" />
      <geometry>
        <mesh
          filename="file://$(find spider_description)/meshes/l4l_link.STL" />
      </geometry>
    </collision>
  </link>
  <joint
    name="l4l_joint"
    type="revolute">
    <origin
      xyz="-0.0126999974848215 0.0886109691786371 0.199179180631636"
      rpy="-1.12769014223129 0 -3.14159265358979" />
    <parent
      link="l4m_link" />
    <child
      link="l4l_link" />
    <axis
      xyz="-1 0 0" />
    <limit
      lower="-2"
      upper="2"
      effort="10.3"
      velocity="5.5" />
  </joint>
  <link
    name="r1u_link">
    <inertial>
      <origin
        xyz="0.148207869574388 -0.113568092535997 0.0262104276586033"
        rpy="0 0 0" />
      <mass
        value="0.121556928492689" />
      <inertia
        ixx="2.98668966703704E-05"
        ixy="6.00793213930533E-06"
        ixz="-1.46755899136436E-07"
        iyy="8.34777185067235E-05"
        iyz="1.67154163892485E-08"
        izz="8.98886606266763E-05" />
    </inertial>
    <visual>
      <origin
        xyz="0 0 0"
        rpy="0 0 0" />
      <geometry>
        <mesh
          filename="file://$(find spider_description)/meshes/r1u_link.STL" />
      </geometry>
      <material
        name="">
        <color
          rgba="0.898039215686275 0.917647058823529 0.929411764705882 1" />
      </material>
    </visual>
    <collision>
      <origin
        xyz="0 0 0"
        rpy="0 0 0" />
      <geometry>
        <mesh
          filename="file://$(find spider_description)/meshes/r1u_link.STL" />
      </geometry>
    </collision>
  </link>
  <joint
    name="r1u_joint"
    type="revolute">
    <origin
      xyz="0.136602935580136 -0.0691615733634508 0.324809965584119"
      rpy="-3.14159265358979 0 0.703227550587687" />
    <parent
      link="base_link" />
    <child
      link="r1u_link" />
    <axis
      xyz="0 0 -1" />
    <limit
      lower="-2"
      upper="2"
      effort="10.3"
      velocity="5.5" />
  </joint>
  <link
    name="r1m_link">
    <inertial>
      <origin
        xyz="0.233140650651849 0.176184289562771 0.135874137693726"
        rpy="0 0 0" />
      <mass
        value="0.161135068968701" />
      <inertia
        ixx="0.000379535016682295"
        ixy="-1.46776707689112E-05"
        ixz="-0.000194760697089458"
        iyy="0.000495080267172652"
        iyz="-2.43786404122665E-05"
        izz="0.000154778948971813" />
    </inertial>
    <visual>
      <origin
        xyz="0 0 0"
        rpy="0 0 0" />
      <geometry>
        <mesh
          filename="file://$(find spider_description)/meshes/r1m_link.STL" />
      </geometry>
      <material
        name="">
        <color
          rgba="0.792156862745098 0.819607843137255 0.933333333333333 1" />
      </material>
    </visual>
    <collision>
      <origin
        xyz="0 0 0"
        rpy="0 0 0" />
      <geometry>
        <mesh
          filename="file://$(find spider_description)/meshes/r1m_link.STL" />
      </geometry>
    </collision>
  </link>
  <joint
    name="r1m_joint"
    type="revolute">
    <origin
      xyz="0.0242 0.089 0.0267"
      rpy="3.1416 0 0" />
    <parent
      link="r1u_link" />
    <child
      link="r1m_link" />
    <axis
      xyz="-1 0 0" />
    <limit
      lower="-2"
      upper="2"
      effort="10.3"
      velocity="5.5" />
  </joint>
  <link
    name="r1l_link">
    <inertial>
      <origin
        xyz="-0.395768344883554 -0.334232912194593 0.193915060541795"
        rpy="0 0 0" />
      <mass
        value="0.232321735211916" />
      <inertia
        ixx="0.00373324494846099"
        ixy="-0.00151046832242664"
        ixz="-0.000700887469750535"
        iyy="0.00155024741868679"
        iyz="-0.00144296353917531"
        izz="0.00390649604901421" />
    </inertial>
    <visual>
      <origin
        xyz="0 0 0"
        rpy="0 0 0" />
      <geometry>
        <mesh
          filename="file://$(find spider_description)/meshes/r1l_link.STL" />
      </geometry>
      <material
        name="">
        <color
          rgba="1 1 1 1" />
      </material>
    </visual>
    <collision>
      <origin
        xyz="0 0 0"
        rpy="0 0 0" />
      <geometry>
        <mesh
          filename="file://$(find spider_description)/meshes/r1l_link.STL" />
      </geometry>
    </collision>
  </link>
  <joint
    name="r1l_joint"
    type="revolute">
    <origin
      xyz="-0.0126999999944641 -0.0992621263509631 0.194090907222879"
      rpy="1.07353625509997 0 -3.14159265358979" />
    <parent
      link="r1m_link" />
    <child
      link="r1l_link" />
    <axis
      xyz="-1 0 0" />
    <limit
      lower="-2"
      upper="2"
      effort="10.3"
      velocity="5.5" />
  </joint>
  <link
    name="r2u_link">
    <inertial>
      <origin
        xyz="0.0393860824583521 -0.229706570908384 0.0262104271103833"
        rpy="0 0 0" />
      <mass
        value="0.121556935225542" />
      <inertia
        ixx="7.87050790167606E-05"
        ixy="1.64067793462395E-05"
        ixz="-4.6023377210421E-08"
        iyy="3.46395364038567E-05"
        iyz="1.40351179115391E-07"
        izz="8.98886619160401E-05" />
    </inertial>
    <visual>
      <origin
        xyz="0 0 0"
        rpy="0 0 0" />
      <geometry>
        <mesh
          filename="file://$(find spider_description)/meshes/r2u_link.STL" />
      </geometry>
      <material
        name="">
        <color
          rgba="0.792156862745098 0.819607843137255 0.933333333333333 1" />
      </material>
    </visual>
    <collision>
      <origin
        xyz="0 0 0"
        rpy="0 0 0" />
      <geometry>
        <mesh
          filename="file://$(find spider_description)/meshes/r2u_link.STL" />
      </geometry>
    </collision>
  </link>
  <joint
    name="r2u_joint"
    type="revolute">
    <origin
      xyz="0.0559114070065679 -0.0854187677387982 0.324809965584119"
      rpy="-3.14159265358979 0 0.131917740473575" />
    <parent
      link="base_link" />
    <child
      link="r2u_link" />
    <axis
      xyz="0 0 -1" />
    <limit
      lower="-2"
      upper="2"
      effort="10.3"
      velocity="5.5" />
  </joint>
  <link
    name="r2m_link">
    <inertial>
      <origin
        xyz="0.0799837281142454 0.392126892410486 0.143742457702955"
        rpy="0 0 0" />
      <mass
        value="0.161135066858505" />
      <inertia
        ixx="0.000489791624189522"
        ixy="-2.26029289337931E-05"
        ixz="-5.01686828810099E-05"
        iyy="0.000425201021002301"
        iyz="-0.000159304331951756"
        izz="0.000114401584961559" />
    </inertial>
    <visual>
      <origin
        xyz="0 0 0"
        rpy="0 0 0" />
      <geometry>
        <mesh
          filename="file://$(find spider_description)/meshes/r2m_link.STL" />
      </geometry>
      <material
        name="">
        <color
          rgba="0.792156862745098 0.819607843137255 0.933333333333333 1" />
      </material>
    </visual>
    <collision>
      <origin
        xyz="0 0 0"
        rpy="0 0 0" />
      <geometry>
        <mesh
          filename="file://$(find spider_description)/meshes/r2m_link.STL" />
      </geometry>
    </collision>
  </link>
  <joint
    name="r2m_joint"
    type="revolute">
    <origin
      xyz="0.0241999999600082 0.0890000003031802 0.0267000001718455"
      rpy="3.14159265358979 0 0" />
    <parent
      link="r2u_link" />
    <child
      link="r2m_link" />
    <axis
      xyz="-1 0 0" />
    <limit
      lower="-2"
      upper="2"
      effort="10.3"
      velocity="5.5" />
  </joint>
  <link
    name="r2l_link">
    <inertial>
      <origin
        xyz="-0.0983765108621166 -0.51368209881784 0.431996473898625"
        rpy="0 0 0" />
      <mass
        value="0.232321735211916" />
      <inertia
        ixx="0.00453799369010132"
        ixy="-0.000448350625760401"
        ixz="-8.90349234682501E-05"
        iyy="0.000426369375121422"
        iyz="-0.00106346632488703"
        izz="0.00422562535093929" />
    </inertial>
    <visual>
      <origin
        xyz="0 0 0"
        rpy="0 0 0" />
      <geometry>
        <mesh
          filename="file://$(find spider_description)/meshes/r2l_link.STL" />
      </geometry>
      <material
        name="">
        <color
          rgba="1 1 1 1" />
      </material>
    </visual>
    <collision>
      <origin
        xyz="0 0 0"
        rpy="0 0 0" />
      <geometry>
        <mesh
          filename="file://$(find spider_description)/meshes/r2l_link.STL" />
      </geometry>
    </collision>
  </link>
  <joint
    name="r2l_joint"
    type="revolute">
    <origin
      xyz="-0.0127 -0.11528 0.18502"
      rpy="0.98907 0 -3.1416" />
    <parent
      link="r2m_link" />
    <child
      link="r2l_link" />
    <axis
      xyz="-1 0 0" />
    <limit
      lower="-2"
      upper="2"
      effort="10.3"
      velocity="5.5" />
  </joint>
  <link
    name="r3u_link">
    <inertial>
      <origin
        xyz="-0.226618738572714 0.053020454285816 0.0262104275521161"
        rpy="0 0 0" />
      <mass
        value="0.121556929243119" />
      <inertia
        ixx="3.49498611571722E-05"
        ixy="1.68154906781804E-05"
        ixz="1.39612861065069E-07"
        iyy="7.83947528584061E-05"
        iyz="-4.82179839090927E-08"
        izz="8.98886605706935E-05" />
    </inertial>
    <visual>
      <origin
        xyz="0 0 0"
        rpy="0 0 0" />
      <geometry>
        <mesh
          filename="file://$(find spider_description)/meshes/r3u_link.STL" />
      </geometry>
      <material
        name="">
        <color
          rgba="0.898039215686275 0.917647058823529 0.929411764705882 1" />
      </material>
    </visual>
    <collision>
      <origin
        xyz="0 0 0"
        rpy="0 0 0" />
      <geometry>
        <mesh
          filename="file://$(find spider_description)/meshes/r3u_link.STL" />
      </geometry>
    </collision>
  </link>
  <joint
    name="r3u_joint"
    type="revolute">
    <origin
      xyz="-0.055911 -0.085419 0.32481"
      rpy="-3.1416 0 -1.7529" />
    <parent
      link="base_link" />
    <child
      link="r3u_link" />
    <axis
      xyz="0 0 -1" />
    <limit
      lower="-2"
      upper="2"
      effort="10.3"
      velocity="5.5" />
  </joint>
  <link
    name="r3m_link">
    <inertial>
      <origin
        xyz="-0.0736230953266375 0.423457416607808 0.138486437412648"
        rpy="0 0 0" />
      <mass
        value="0.16113506827159" />
      <inertia
        ixx="0.000484872983718575"
        ixy="3.36498500323986E-05"
        ixz="6.34437359056575E-05"
        iyy="0.000402890228935658"
        iyz="-0.000177192343327242"
        izz="0.000141631016548907" />
    </inertial>
    <visual>
      <origin
        xyz="0 0 0"
        rpy="0 0 0" />
      <geometry>
        <mesh
          filename="file://$(find spider_description)/meshes/r3m_link.STL" />
      </geometry>
      <material
        name="">
        <color
          rgba="0.792156862745098 0.819607843137255 0.933333333333333 1" />
      </material>
    </visual>
    <collision>
      <origin
        xyz="0 0 0"
        rpy="0 0 0" />
      <geometry>
        <mesh
          filename="file://$(find spider_description)/meshes/r3m_link.STL" />
      </geometry>
    </collision>
  </link>
  <joint
    name="r3m_joint"
    type="revolute">
    <origin
      xyz="0.0890000004286123 -0.0241999983852906 0.0267000103662986"
      rpy="3.14159265358979 0 -1.5707963267949" />
    <parent
      link="r3u_link" />
    <child
      link="r3m_link" />
    <axis
      xyz="-1 0 0" />
    <limit
      lower="-2"
      upper="2"
      effort="10.3"
      velocity="5.5" />
  </joint>
  <link
    name="r3l_link">
    <inertial>
      <origin
        xyz="0.143384815976551 -0.527848884315122 0.447668295836574"
        rpy="0 0 0" />
      <mass
        value="0.232321735211916" />
      <inertia
        ixx="0.00451021639580909"
        ixy="0.000561366174761743"
        ixz="9.11369008439715E-05"
        iyy="0.000367824087074563"
        iyz="-0.000892687549937647"
        izz="0.00431194793327837" />
    </inertial>
    <visual>
      <origin
        xyz="0 0 0"
        rpy="0 0 0" />
      <geometry>
        <mesh
          filename="file://$(find spider_description)/meshes/r3l_link.STL" />
      </geometry>
      <material
        name="">
        <color
          rgba="1 1 1 1" />
      </material>
    </visual>
    <collision>
      <origin
        xyz="0 0 0"
        rpy="0 0 0" />
      <geometry>
        <mesh
          filename="file://$(find spider_description)/meshes/r3l_link.STL" />
      </geometry>
    </collision>
  </link>
  <joint
    name="r3l_joint"
    type="revolute">
    <origin
      xyz="-0.0126999983853409 -0.115843507306277 0.1846741333931"
      rpy="0.986037147990987 0 3.14159265358979" />
    <parent
      link="r3m_link" />
    <child
      link="r3l_link" />
    <axis
      xyz="-1 0 0" />
    <limit
      lower="-2"
      upper="2"
      effort="10.3"
      velocity="5.5" />
  </joint>
  <link
    name="r4u_link">
    <inertial>
      <origin
        xyz="0 0 0"
        rpy="0 0 0" />
      <mass
        value="0" />
      <inertia
        ixx="0"
        ixy="0"
        ixz="0"
        iyy="0"
        iyz="0"
        izz="0" />
    </inertial>
    <visual>
      <origin
        xyz="0 0 0"
        rpy="0 0 0" />
      <geometry>
        <mesh
          filename="file://$(find spider_description)/meshes/r4u_link.STL" />
      </geometry>
      <material
        name="">
        <color
          rgba="1 1 1 1" />
      </material>
    </visual>
    <collision>
      <origin
        xyz="0 0 0"
        rpy="0 0 0" />
      <geometry>
        <mesh
          filename="file://$(find spider_description)/meshes/r4u_link.STL" />
      </geometry>
    </collision>
  </link>
  <joint
    name="r4u_joint"
    type="revolute">
    <origin
      xyz="-0.135325236036619 -0.0657959406032559 0.324691528435297"
      rpy="-3.14159265358979 0 -0.69315919605786" />
    <parent
      link="base_link" />
    <child
      link="r4u_link" />
    <axis
      xyz="0 0 -1" />
    <limit
      lower="-2"
      upper="2"
      effort="10.3"
      velocity="5.5" />
  </joint>
  <link
    name="r4m_link">
    <inertial>
      <origin
        xyz="-0.250871434190705 0.256623432004968 0.143579897255662"
        rpy="0 0 0" />
      <mass
        value="0.161135069104928" />
      <inertia
        ixx="0.000419384029729634"
        ixy="1.47050965842845E-05"
        ixz="0.0001654110489314"
        iyy="0.000494126538565069"
        iyz="-3.13340965808053E-05"
        izz="0.000115883664750578" />
    </inertial>
    <visual>
      <origin
        xyz="0 0 0"
        rpy="0 0 0" />
      <geometry>
        <mesh
          filename="file://$(find spider_description)/meshes/r4m_link.STL" />
      </geometry>
      <material
        name="">
        <color
          rgba="0.968627450980392 0.258823529411765 0.258823529411765 1" />
      </material>
    </visual>
    <collision>
      <origin
        xyz="0 0 0"
        rpy="0 0 0" />
      <geometry>
        <mesh
          filename="file://$(find spider_description)/meshes/r4m_link.STL" />
      </geometry>
    </collision>
  </link>
  <joint
    name="r4m_joint"
    type="revolute">
    <origin
      xyz="0.0242000000023438 0.0890000000051655 0.0267000000007527"
      rpy="3.14159265358979 0 0" />
    <parent
      link="r4u_link" />
    <child
      link="r4m_link" />
    <axis
      xyz="-1 0 0" />
    <limit
      lower="-2"
      upper="2"
      effort="10.3"
      velocity="5.5" />
  </joint>
  <link
    name="r4l_link">
    <inertial>
      <origin
        xyz="0.377127260198447 -0.390248671018137 0.171658866000629"
        rpy="0 0 0" />
      <mass
        value="0.232321735211916" />
      <inertia
        ixx="0.00397816412512949"
        ixy="0.00111695491575896"
        ixz="0.000878309267851669"
        iyy="0.00219389835229997"
        iyz="-0.00193984687110624"
        izz="0.00301792593873255" />
    </inertial>
    <visual>
      <origin
        xyz="0 0 0"
        rpy="0 0 0" />
      <geometry>
        <mesh
          filename="file://$(find spider_description)/meshes/r4l_link.STL" />
      </geometry>
      <material
        name="">
        <color
          rgba="1 1 1 1" />
      </material>
    </visual>
    <collision>
      <origin
        xyz="0 0 0"
        rpy="0 0 0" />
      <geometry>
        <mesh
          filename="file://$(find spider_description)/meshes/r4l_link.STL" />
      </geometry>
    </collision>
  </link>
  <joint
    name="r4l_joint"
    type="revolute">
    <origin
      xyz="-0.0127000000193744 -0.144696416510389 0.163055809591358"
      rpy="0.820466328484267 0 -3.14159265358979" />
    <parent
      link="r4m_link" />
    <child
      link="r4l_link" />
    <axis
      xyz="-1 0 0" />
    <limit
      lower="-2"
      upper="2"
      effort="10.3"
      velocity="5.5" />
  </joint>
  <link name="imu_link">
    <visual>
      <geometry>
        <box size="0.1 0.1 0.1"/>
      </geometry>
    </visual>

    <collision>
      <geometry>
        <box size="0.1 0.1 0.1"/>
      </geometry>
    </collision>

    <inertia
        ixx="0.00397816412512949"
        ixy="0.00111695491575896"
        ixz="0.000878309267851669"
        iyy="0.00219389835229997"
        iyz="-0.00193984687110624"
        izz="0.00301792593873255" />
  </link>

  <joint name="imu_joint" type="fixed">
    <parent link="base_link"/>
    <child link="imu_link"/>
    <origin xyz="0 0 0.354546759775775"/>
  </joint>

  <gazebo reference="imu_link">
    <sensor name="imu_sensor" type="imu">
    <plugin filename="libgazebo_ros_imu_sensor.so" name="imu_plugin">
        <ros>
          <namespace>/demo</namespace>
          <remapping>~/out:=imu</remapping>
        </ros>
        <initial_orientation_as_reference>false</initial_orientation_as_reference>
      </plugin>
      <always_on>true</always_on>
      <update_rate>100</update_rate>
      <visualize>true</visualize>
      <imu>
        <angular_velocity>
          <x>
            <noise type="gaussian">
              <mean>0.0</mean>
              <stddev>2e-4</stddev>
              <bias_mean>0.0000075</bias_mean>
              <bias_stddev>0.0000008</bias_stddev>
            </noise>
          </x>
          <y>
            <noise type="gaussian">
              <mean>0.0</mean>
              <stddev>2e-4</stddev>
              <bias_mean>0.0000075</bias_mean>
              <bias_stddev>0.0000008</bias_stddev>
            </noise>
          </y>
          <z>
            <noise type="gaussian">
              <mean>0.0</mean>
              <stddev>2e-4</stddev>
              <bias_mean>0.0000075</bias_mean>
              <bias_stddev>0.0000008</bias_stddev>
            </noise>
          </z>
        </angular_velocity>
        <linear_acceleration>
          <x>
            <noise type="gaussian">
              <mean>0.0</mean>
              <stddev>1.7e-2</stddev>
              <bias_mean>0.1</bias_mean>
              <bias_stddev>0.001</bias_stddev>
            </noise>
          </x>
          <y>
            <noise type="gaussian">
              <mean>0.0</mean>
              <stddev>1.7e-2</stddev>
              <bias_mean>0.1</bias_mean>
              <bias_stddev>0.001</bias_stddev>
            </noise>
          </y>
          <z>
            <noise type="gaussian">
              <mean>0.0</mean>
              <stddev>1.7e-2</stddev>
              <bias_mean>0.1</bias_mean>
              <bias_stddev>0.001</bias_stddev>
            </noise>
          </z>
        </linear_acceleration>
      </imu>
    </sensor>
  </gazebo>
</robot>